Workbook
Name \M: #REF!
Name __: '[1]Trial Balance'!#REF!
Name ___: '[1]Trial Balance'!#REF!
Name ____________apr2: [2]LIBERIA!#REF!
Name ____________aug1: [2]LIBERIA!#REF!
Name ____________aug2: [2]LIBERIA!#REF!
Name ____________dec1: [2]LIBERIA!#REF!
Name ____________dec2: [2]LIBERIA!#REF!
Name ____________feb1: [2]LIBERIA!#REF!
Name ____________feb2: [2]LIBERIA!#REF!
Name ____________jul1: [2]LIBERIA!#REF!
Name ____________jul2: [2]LIBERIA!#REF!
Name ____________jun1: [2]LIBERIA!#REF!
Name ____________jun2: [2]LIBERIA!#REF!
Name ____________mar1: [2]LIBERIA!#REF!
Name ____________mar2: [2]LIBERIA!#REF!
Name ____________may1: [2]LIBERIA!#REF!
Name ____________may2: [2]LIBERIA!#REF!
Name ____________nov1: [2]LIBERIA!#REF!
Name ____________nov2: [2]LIBERIA!#REF!
Name ____________oct1: [2]LIBERIA!#REF!
Name ____________oct2: [2]LIBERIA!#REF!
Name ____________sep1: [2]LIBERIA!#REF!
Name ____________sep2: [2]LIBERIA!#REF!
Name ___________apr1: [2]LIBERIA!#REF!
Name ___________apr2: [2]LIBERIA!#REF!
Name ___________aug1: [2]LIBERIA!#REF!
Name ___________aug2: [2]LIBERIA!#REF!
Name ___________dec1: [2]LIBERIA!#REF!
Name ___________dec2: [2]LIBERIA!#REF!
Name ___________feb1: [2]LIBERIA!#REF!
Name ___________feb2: [2]LIBERIA!#REF!
Name ___________jul1: [2]LIBERIA!#REF!
Name ___________jul2: [2]LIBERIA!#REF!
Name ___________jun1: [2]LIBERIA!#REF!
Name ___________jun2: [2]LIBERIA!#REF!
Name ___________mar1: [2]LIBERIA!#REF!
Name ___________mar2: [2]LIBERIA!#REF!
Name ___________may1: [2]LIBERIA!#REF!
Name ___________may2: [2]LIBERIA!#REF!
Name ___________nov1: [2]LIBERIA!#REF!
Name ___________nov2: [2]LIBERIA!#REF!
Name ___________oct1: [2]LIBERIA!#REF!
Name ___________oct2: [2]LIBERIA!#REF!
Name ___________sep1: [2]LIBERIA!#REF!
Name ___________sep2: [2]LIBERIA!#REF!
Name __________apr1: [2]LIBERIA!#REF!
Name __________apr2: [2]LIBERIA!#REF!
Name __________aug1: [2]LIBERIA!#REF!
Name __________aug2: [2]LIBERIA!#REF!
Name __________dec1: [2]LIBERIA!#REF!
Name __________dec2: [2]LIBERIA!#REF!
Name __________feb1: [2]LIBERIA!#REF!
Name __________feb2: [2]LIBERIA!#REF!
Name __________jul1: [2]LIBERIA!#REF!
Name __________jul2: [2]LIBERIA!#REF!
Name __________jun1: [2]LIBERIA!#REF!
Name __________jun2: [2]LIBERIA!#REF!
Name __________mar1: [2]LIBERIA!#REF!
Name __________mar2: [2]LIBERIA!#REF!

Sheet Summary
A1: Nurul Faruk Hasan & Co
A2: Chartered Accountants
A4: Client name: American Life Insurance Company, Bangladesh Branch (MetLife)
A5: Accounting period: 01 January 2025 to 31 December 2025
A6: Prepared by: Md. Tamzid | C6: Date: 25 February 2026
A7: Reviewed by: Ranti Saha | C7: Date: 25 February 2026
A8: Further reviewed by: Faruk Uddin Ahammed, FCA | C8: Date: 04 March 2026
A10: Subject: | B10: Summary sheet of work paper on provision for income tax
A12: RoMM: | B12: 1. Income tax computation is not prepared as per the requirement of the tax authority. 2. Advance income tax is not recorded at correct amount.
A14: Assertion: | B14: 1. Completeness, Valuation & Allocation 2. Accuracy
A17: Contents:
A18: Sl no | B18: Sheet name | C18: Audit procedure
A19: 1 | B19: Top sheet | C19: Topsheet and breakup of current income tax (note 17)
A20: 2 | B20: GL Reconciliation | C20: Tie out GL amount with TB balance
A21: 3 | B21: Prior year adjustment | C21: Calculation of prior year adjustment amount as per note 17
A22: 4 | B22: Tax Calculation | C22: Calculation of current year tax provision amount based on total income as per actuarial valuation
A23: 5 | B23: Tax paid in advance & deducted | C23: Breakup of the tax paid in advance & deducted at source
A24: 6 | B24: TDS | C24: Breakup of the tax withheld by different organization
A25: 7 | B25: Tax paid for 2024 | C25: Breakup of the tax amounts paid for income year 2024
A26: 8 | B26: Regulation | C26: Provision of Act and comparison of old and new act to develop tax provision amount
A27: 9 | B27: Return 2024 | C27: Income tax return FY 2024 submitted by management
A30: Sl no | B30: ET queries | C30: Mgt comments
A31: 1 | B31: Breakup of the Tax paid for 2021 along with supporting documents (Note 17.1; BDT: 913,537,089). How did the figure came? | C31: This is regarding the amount paid in advance for the purpose of income tax provision made in 2021.
A32: 2 | B32: Breakup of Advance Income Tax paid during the year & deducted at source along with supporting documents (Note 17.1; BDT 1,470,098,235). How did the figure came? | C32: Amount deposited as advance income tax for income year from 01 January 2022 to 31 December 2022.
A33: 3 | B33: Advance income tax paid during the year - challans did not match with the financial statements. Requesting the management to reconcile the amount and walk us through. | C33: To be reconciled by Rajibul Bhai and shall be shared later
A34: 4 | B34: Regarding the letter issued by IDRA, we are requesting to provide us the breakup of the amount BDT 2,410,000,000 which was mentioned in the letter and also provide the supporting documents. | C34: Breakup of the amount shall be shared by Rajibul Bhai
A35: 5 | B35: Latest CA firm report on International Transaction. | C35: Last 2019 which was provided in last year
A36: 6 | B36: GLs of Income tax provision (1568000090, 1568000094, 2700000020)
A37: 7 | B37: 107EE: Why the balance of Shareholders portion of profit did not match with the financial statements? | C37: Includes WPPF calculation which shall be provided by Rajibul Bhai
A38: 8 | B38: Tax paid for 2021: how the amount has been allocated into par/non-par? | C38: Includes WPPF calculation which shall be provided by Rajibul Bhai

Sheet GL Reconciliation
B1: Nurul Faruk Hasan & Co
B2: Chartered Accountants
B4: Client name: American Life Insurance Company, Bangladesh Branch (MetLife)
B5: Accounting period: 01 January 2025 to 31 December 2025
B6: Prepared by: Md. Tamzid | H6: Date: 25 February 2026
B7: Reviewed by: Ranti Saha | H7: Date: 25 February 2026
B8: Further reviewed by: Faruk Uddin Ahammed, FCA | H8: Date: 04 March 2026
B11: GL Code | D11: Amount as per TB | E11: Opening Balance | F11: TB activity | G11: GL movement | H11: Difference | I11: Reference
B12: 1568000090 | C12: 1,028,530,770 | D12: 1.7304513e+09 | E12: 1.0176557e+09 | F12: =D12-E12 | G12: =SUM(TDS!L55) | H12: =F12-G12 | I12: TDS!A1
B13: 1568000094 | C13: 954,817,177 | D13: 8.1609499e+08 | E13: 9.2965969e+08 | F13: =D13-E13 | G13: =GL!L180 | H13: =F13-G13 | I13: GL!1568000094
B14: 2700000020 | D14: -3119803322 | E14: -3.3382075e+09 | F14: =D14-E14 | G14: =GL!L166 | H14: =F14-G14 | I14: GL!A1
B15: Grand Total | D15: =SUM(D12:D14)
D16: FS

Sheet Top sheet
B1: Nurul Faruk Hasan & Co
B2: Chartered Accountants
B4: Client name: American Life Insurance Company, Bangladesh Branch (MetLife)
B5: Accounting period: 01 January 2025 to 31 December 2025
B6: Prepared by: Md. Tamzid | H6: Date: 25 February 2026
B7: Reviewed by: Ranti Saha | H7: Date: 25 February 2026
B8: Further reviewed by: Faruk Uddin Ahammed, FCA | H8: Date: 04 March 2026
B10: Subject: Topsheet of current income tax
B11: Purpose: To match the amount of books of accounts with the financial statements and check accuracy and completeness of the books of accounts.
B13: PROVISION FOR INCOME TAX | C13: Note | D13: 2025 | E13: 2024 | F13: 2023 | G13: 2022 | H13: Ref | I13: Remarks
B15: Opening balance | D15: 1390892074 | E15: =F21 | F15: 1236756243 | G15: 796201334 | H15: Prior year FS
B16: Add: Provisions made during the year:
B17: Provision for Prior Year / Adjustments | D17: -384275815 | E17: -4.845626e+08 | F17: -72117494 | G17: -51195073 | H17: Prior year adjustment'!A1
B18: Provision for Current Year | D18: 3202938943 | E18: 3338209365 | F18: 3098439336 | G18: 2.8753853e+09 | H18: Draft tax computation based on the draft actuarial valuation (see tab: Tax Calculation PBC) | I18: Based on ET's checking, it is concluded, the company adequately kept provision and it is in line with the provision of the relevant regulation. Ref: Tab name - "Regulation" and "Return 2024".
B19: Total provision | D19: =SUM(D17:D18) | E19: =SUM(E17:E18) | F19: =SUM(F17:F18) | G19: =SUM(G17:G18)
B20: Less: Payments / adjustments made during the year | C20: 17.1 | D20: 3055080217 | E20: 2577844224 | F20: 3147988550 | G20: 2.3836353e+09 | H20: Top sheet'!A13
D21: =D15+D19-D20 | E21: =E15+E19-E20 | F21: =F15+F19-F20 | G21: =G15+G19-G20
B24: Note 17.1
B25: Payment / adjustment represents as follows
B27: Tax paid in advance & deducted at source | D27: 2.0224943e+09 | E27: 1432366656 | F27: 1483530767 | G27: 1.4700982e+09 | H27: Tax paid in advance & deducted'!A1
B28: Tax paid for prior year | D28: 1032585957 | E28: 1145477568 | F28: 1664457783 | G28: 9.1353709e+08 | H28: Tax paid for 2024
D29: =SUM(D27:D28) | E29: =SUM(E27:E28) | F29: =SUM(F27:F28) | G29: =SUM(G27:G28)
B33: Conclusion:
B34: No exception noted

Sheet Prior year adjustment
A1: Nurul Faruk Hasan & Co
A2: Chartered Accountants
A4: Client name: American Life Insurance Company, Bangladesh Branch (MetLife)
A5: Accounting period: 01 January 2025 to 31 December 2025
A6: Prepared by: Md. Tamzid | G6: Date: 25 February 2026
A7: Reviewed by: Ranti Saha | G7: Date: 25 February 2026
A8: Further reviewed by: Faruk Uddin Ahammed, FCA | G8: Date: 04 March 2026
A9: Subject: Calculation of prior year adjustment
A10: Purpose: To adjust the amount with current year current tax provision
A13: Particulars | B13: Particulars | C13: Amount | D13: Amount | E13: Amount | F13: Amount | G13: Reference
A14: 1. Tax True Down
B15: As per Tax Return of 2024-2025 | E15: =E32 | G15: Checked with Income Tax Return of 2024-25
B16: Prior year Provision | E16: ='Top sheet'!E18 | G16: Checked with Prior Year Audited Financial Statements (Revenue Account)
F17: =E15-E16
A18: 2. Additional Provision
B19: Taxable Income as per Provision:
B20: Taxable Income Before disallowance if 75% on nonpar not considered (A):
B21: Shareholder Portion | C21: 2415057751 | G21: Checked with "Annexure H" of Computation of Total Shareholders' Income from Tax Computation for AY 25-26
B22: Participating Life | C22: 2555337595 | G22: Checked with "Annexure E" of Computation of Total Income under Section 47 of the Income Tax Act from Tax Computation for AY 25-26
B23: Non-Participating Life | C23: 2245402764 | G23: Checked with "Annexure E" of Computation of Total Income under Section 47 of the Income Tax Act from Tax Computation for AY 25-26
D24: =SUM(C21:C23)
B25: Total Disallowance (B) | D25: 64139947 | G25: Checked with "Annexure E" of Computation of Total Income under Section 47 of the Income Tax Act from Tax Computation for AY 25-26
B26: Taxable Income if 75% on nonpar not considered (C=A+B): | D26: =D24+D25
B27: Tax as per Taxable Income if 75% on nonpar not considered (D=C*40%): | E27: =ROUNDDOWN(D26*40%,0)
B29: Taxable Income as per Return:
B30: Taxable Income Before disallowance (As per Return) (E) | D30: 6033367859 | G30: Checked with Income Tax Return of 2024-25
B31: Capital Gain (As per Return) (F) | D31: 3625707 | G31: Checked with Income Tax Return of 2024-25
B32: Tax as per Tax Return: (G=E*40%+F*15%) | E32: =ROUNDDOWN((D30*40%)+(D31*15%),0)
F33: =E27-E32
A34: 3. Additional Tax Demand from ADR for the year 2018 | F34: 41958325 | G34: Checked with ADR for the year 2018
A35: Total Prior year Adjustments (1+2+3) | F35: =F17+F33+F34
A36: As per FS | F36: ='Top sheet'!D17
A37: Difference | F37: =F35-F36
A42: Conclusion:
A43: No exception noted

Sheet Tax paid in advance & deducted
A1: Nurul Faruk Hasan & Co | W1: This amount relates to TDS deductions on interest income from one bond and three FDRs (Bond ID: BME5RRWL5; FDR IDs: BME5GJ3T0, BME5GJ444, and BME5GJ7K5). The interest was received on January 1, 2024, net of TDS—bond proceeds were credited to the Prime Bank account, while FDR proceeds were received through Standard Chartered Bank. The ET has verified the amounts against the respective bank receipts.
A2: Chartered Accountants
A4: Client name: American Life Insurance Company, Bangladesh Branch (MetLife)
A5: Accounting period: 01 January 2025 to 31 December 2025
A6: Prepared by: Md. Tamzid | G6: Date: 25 February 2026
A7: Reviewed by: Ranti Saha | G7: Date: 25 February 2026
A8: Further reviewed by: Faruk Uddin Ahammed, FCA | G8: Date: 04 March 2026
A9: Subject: Breakup of Tax paid in advance & deducted at source
A11: Amount deposited as advance income tax for income year from 01 January 2024 to 31 December 2024
A14: Particulars | B14: Amount paid | C14: Checked with | D14: Ref | E14: Submission Date | F14: Remarks
A15: Installment 1 of 2026-2027 | B15: 92000000 | C15: Tax Challan/Money receipt of tax submission | D15: Checked with Installment 1 of 2026-2027 | E15: 45914
A16: Excess Payment | B16: 200010091 | C16: As per Tax Return 2023 under "39 Deficit or Excess (refundable)" | D16: Checked with Income Tax Return of 2024-25 | F16: =Remarks!A3
B17: =SUM(B15:B16)
A18: TDS withheld by different organizations | B18: =TDS!B53 | C18: TDS withheld GL Code 1568000090 | D18: =TDS!A53 | F18: =Remarks!A3
A19: Tax paid in advance and deducted at source | B19: =B17+B18
A20: Amount shown in FS | B20: ='Top sheet'!D27
A21: Difference | B21: =B19-B20

Sheet TDS
A1: Nurul Faruk Hasan & Co
A2: Chartered Accountants
A4: Client name: American Life Insurance Company, Bangladesh Branch (MetLife)
A5: Accounting period: 01 January 2025 to 31 December 2025
A6: Prepared by: Md. Tamzid | G6: Date: 25 February 2026
A7: Reviewed by: Ranti Saha | G7: Date: 25 February 2026
A8: Further reviewed by: Faruk Uddin Ahammed, FCA | G8: Date: 04 March 2026
A9: Subject: TDS withheld by different organizations
A12: Key | B12: Account | C12: Product | D12: OU | E12: Dept | F12: Par/Npar | G12: FS | H12: Note | I12: Final TB
A13: 1568000090_360004_36007575 | B13: 1568000090 | C13: 360004 | D13: 36320000 | E13: 36007575 | F13: P_L | G13: BS_L_L08 | H13: BS_L_L08.01 | I13: 180000
A14: 1568000090_360004_36050022 | B14: 1568000090 | C14: 360004 | D14: 36320000 | E14: 36050022 | F14: P_L | G14: BS_L_L08 | H14: BS_L_L08.01 | I14: 197500
A15: 1568000090_360004_36050051 | B15: 1568000090 | C15: 360004 | D15: 36320000 | E15: 36050051 | F15: P_L | G15: BS_L_L08 | H15: BS_L_L08.01 | I15: 215000
A16: 1568000090_360004_36050204 | B16: 1568000090 | C16: 360004 | D16: 36320000 | E16: 36050204 | F16: P_L | G16: BS_L_L08 | H16: BS_L_L08.01 | I16: 75000
A17: 1568000090_360004_36050254 | B17: 1568000090 | C17: 360004 | D17: 36320000 | E17: 36050254 | F17: P_L | G17: BS_L_L08 | H17: BS_L_L08.01 | I17: 165000
A18: 1568000090_360004_36050805 | B18: 1568000090 | C18: 360004 | D18: 36320000 | E18: 36050805 | F18: P_L | G18: BS_L_L08 | H18: BS_L_L08.01 | I18: 90000
A19: 1568000090_360004_36071800 | B19: 1568000090 | C19: 360004 | D19: 36320000 | E19: 36071800 | F19: P_L | G19: BS_L_L08 | H19: BS_L_L08.01 | I19: 103451
A20: 1568000090_360004_50101000 | B20: 1568000090 | C20: 360004 | D20: 36320000 | E20: 50101000 | F20: P_L | G20: BS_L_L08 | H20: BS_L_L08.01 | I20: 4117500
A21: 1568000090_360004_50102000 | B21: 1568000090 | C21: 360004 | D21: 36320000 | E21: 50102000 | F21: P_L | G21: BS_L_L08 | H21: BS_L_L08.01 | I21: 127500
A22: 1568000090_360004_50103000 | B22: 1568000090 | C22: 360004 | D22: 36320000 | E22: 50103000 | F22: P_L | G22: BS_L_L08 | H22: BS_L_L08.01 | I22: 465000
A23: 1568000090_360004_50104000 | B23: 1568000090 | C23: 360004 | D23: 36320000 | E23: 50104000 | F23: P_L | G23: BS_L_L08 | H23: BS_L_L08.01 | I23: 217500
A24: 1568000090_360004_50201000 | B24: 1568000090 | C24: 360004 | D24: 36320000 | E24: 50201000 | F24: P_L | G24: BS_L_L08 | H24: BS_L_L08.01 | I24: 52500
... A44: 1568000090_369805_50601000 | B44: 1568000090 | C44: 369805 | D44: 36390000 | E44: 50601000 | F44: SH | G44: BS_L_L08 | H44: BS_L_L08.01 | I44: 1436968
G45: Total | I45: =SUM(I13:I44)
A47: Particulars | B47: Amount
A48: Opening Balance | B48: 1.0176557e+09
A49: Closing Balance | B49: =I45
A50: During the year movement | B50: =ABS(B48-B49)
A51: Amount as per GL | B51: =L55
A52: Difference | B52: =B50-B51
A53: TDS withheld by different organizations | B53: =L55-L254
A55: Transaction during the year: | L55: =SUM(L57:L255)
A56: LEDGER | B56: FISCAL_YEAR | C56: ACCOUNTING_PERIOD | D56: ACCOUNT | E56: DESCR | F56: PRODUCT | G56: OPERATING_UNIT | H56: DEPTID | I56: JOURNAL_ID | J56: JOURNAL_DATE | K56: FOREIGN_CURRENCY | L56: Sum of FOREIGN_AMOUNT
A57: LCOMN_BASE | B57: 2025 | C57: 1 | D57: 1568000090 | E57: FEDERAL INCOME TAX RECEIVABLE | F57: 360004 | G57: 36320000 | H57: 50101000 | I57: APAA618706 | J57: 45664 | K57: BDT | L57: 75000
A58: LCOMN_BASE | B58: 2025 | C58: 1 | D58: 1568000090 | E58: FEDERAL INCOME TAX RECEIVABLE | F58: 361396 | G58: 36310000 | H58: 50601000 | I58: SV01413961 | J58: 45672 | K58: BDT | L58: 2106750.2
A59: LCOMN_BASE | B59: 2025 | C59: 1 | D59: 1568000090 | E59: FEDERAL INCOME TAX RECEIVABLE | F59: 360004 | G59: 36320000 | H59: 50601000 | I59: SV01419302 | J59: 45684 | K59: BDT | L59: 12436153
A60: LCOMN_BASE | B60: 2025 | C60: 1 | D60: 1568000090 | E60: FEDERAL INCOME TAX RECEIVABLE | F60: 360004 | G60: 36320000 | H60: 50601000 | I60: SV01420639 | J60: 45687 | K60: BDT | L60: 41053.2
A61: LCOMN_BASE | B61: 2025 | C61: 1 | D61: 1568000090 | E61: FEDERAL INCOME TAX RECEIVABLE | F61: 360004 | G61: 36320000 | H61: 50601000 | I61: SV01421580 | J61: 45688 | K61: BDT | L61: 68799088
A62: LCOMN_BASE | B62: 2025 | C62: 1 | D62: 1568000090 | E62: FEDERAL INCOME TAX RECEIVABLE | F62: 360004 | G62: 36320000 | H62: 50601000 | I62: 622929 | J62: 45688 | K62: BDT | L62: 103764.83
A63: LCOMN_BASE | B63: 2025 | C63: 1 | D63: 1568000090 | E63: FEDERAL INCOME TAX RECEIVABLE | F63: 360004 | G63: 36320000 | H63: 50992000 | I63: 623728 | J63: 45688 | K63: BDT | L63: 99002.56
A64: LCOMN_BASE | B64: 2025 | C64: 1 | D64: 1568000090 | E64: FEDERAL INCOME TAX RECEIVABLE | F64: 361396 | G64: 36310000 | H64: 50601000 | I64: SV01421580 | J64: 45688 | K64: BDT | L64: 3031223.2
...

Sheet TDS Details
A1: Nurul Faruk Hasan & Co
A2: Chartered Accountants
A4: Client name: American Life Insurance Company, Bangladesh Branch (MetLife)
A5: Accounting period: 01 January 2025 to 31 December 2025
A6: Prepared by: Md. Tamzid | G6: Date: 25 February 2026
A7: Reviewed by: Ranti Saha | G7: Date: 25 February 2026
A8: Further reviewed by: Faruk Uddin Ahammed, FCA | G8: Date: 04 March 2026
A9: Subject: Breakup of selected TDS withheld against different organizations
A13: Date | B13: Journal Id | C13: Account | D13: Account Description | E13: Line Description | F13: DR | G13: (CR) | H13: Amount | I13: ET Checking
A14: 45712 | B14: SJ01430072 | C14: 1568000020 | D14: Sus Asst St Bd A/R Dispty | E14: BME6QART0205 | F14: 2.5116289e+08 | G14: 0 | H14: 2.5116289e+08
A15: 45712 | B15: SJ01430072 | C15: 4390000086 | D15: Int Income Cash-CDs < 1 Yr | E15: BME6QART0205 | F15: 0 | G15: -6649408.2 | H15: -6649408.2
A16: 45712 | B16: SJ01430072 | C16: 1080000600 | D16: Cash-CDs Maturing in < 1 Year | E16: BME6QART0205 | F16: 0 | G16: -2.4451348e+08 | H16: -2.4451348e+08
A17: 45716 | B17: SJ01432133 | C17: 4390000086 | D17: Int Income Cash-CDs < 1 Yr | E17: BME6QART0205 | F17: 6649408.2 | G17: 0 | H17: 6649408.2
A18: 45716 | B18: SJ01432133 | C18: 1080000600 | D18: Cash-CDs Maturing in < 1 Year | E18: BME6QART0205 | F18: 0 | G18: -2.4451348e+08 | H18: -2.4451348e+08
A19: 45716 | B19: SJ01432133 | C19: 1568000020 | D19: Sus Asst St Bd A/R Dispty | E19: BME6QART0205 | F19: 0 | G19: -2.5116289e+08 | H19: -2.5116289e+08
A20: 45716 | B20: SJ01432133 | C20: 4390000086 | D20: Int Income Cash-CDs < 1 Yr | E20: BME6QART0205 | F20: 0 | G20: -6798829.8 | H20: -6798829.8
A21: 45716 | B21: SJ01432133 | C21: 1080000600 | D21: Cash-CDs Maturing in < 1 Year | E21: BME6QART0205 | F21: 2.4451348e+08 | G21: 0 | H21: 2.4451348e+08
A22: 45716 | B22: SJ01432133 | C22: 1568000020 | D22: Sus Asst St Bd A/R Dispty | E22: BME6QART0205 | F22: 2.5131231e+08 | G22: 0 | H22: 2.5131231e+08
A23: 45716 | B23: SV01432137 | C23: 1568000090 | D23: FEDERAL INCOME TAX RECEIVABLE | E23: BME6QART0-Cash | F23: 1359766 | G23: 0 | H23: 1359766 | I23: Tested under investement FDR_Encashment & Renewal
A24: 45716 | B24: SV01432137 | C24: 1568000020 | D24: Sus Asst St Bd A/R Dispty | E24: BME6QART0-Cash | F24: 0 | G24: -1359766 | H24: -1359766
A25: 45716 | B25: SV01432137 | C25: 1568000020 | D25: Sus Asst St Bd A/R Dispty | E25: BME6QART0-Cash | F25: 0 | G25: -230 | H25: -230
A26: 45716 | B26: SV01432137 | C26: 1568000020 | D26: Sus Asst St Bd A/R Dispty | E26: BME6QART0-Cash | F26: 0 | G26: -2.4995231e+08 | H26: -2.4995231e+08
A27: 45716 | B27: SV01432137 | C27: 1568000150 | D27: cash match suspense | E27: BME6QART0-Cash | F27: 2.4995231e+08 | G27: 0 | H27: 2.4995231e+08
A28: 45716 | B28: SV01432137 | C28: 4430005300 | D28: Inv Exp and Taxes O/T RE | E28: BME6QART0-Cash | F28: 230 | G28: 0 | H28: 230
A29: 45783 | B29: SJ01456993 | C29: 1170000200 | D29: Bonds Short Term | E29: BME6P3KF4205 | F29: 0 | G29: -2.9108802e+08 | H29: -2.9108802e+08
A30: 45783 | B30: SJ01456993 | C30: 4390000052 | D30: Int Rec From Bonds St | E30: BME6P3KF4205 | F30: 0 | G30: -15645981 | H30: -15645981
A31: 45783 | B31: SJ01456993 | C31: 1568000040 | D31: Sus Asst Lt Bd A/R Dispty | E31: BME6P3KF4205 | F31: 3.06734e+08 | G31: 0 | H31: 3.06734e+08
A32: 45790 | B32: SJ01459380 | C32: 4390000052 | D32: Int Rec From Bonds St | E32: BME6P3KF4205 | F32: 0 | G32: -15178579 | H32: -15178579
A33: 45790 | B33: SJ01459380 | C33: 1568000040 | D33: Sus Asst Lt Bd A/R Dispty | E33: BME6P3KF4205 | F33: 3.062666e+08 | G33: 0 | H33: 3.062666e+08
A34: 45790 | B34: SJ01459380 | C34: 1568000040 | D34: Sus Asst Lt Bd A/R Dispty | E34: BME6P3KF4205 | F34: 0 | G34: -3.06734e+08 | H34: -3.06734e+08
A35: 45790 | B35: SJ01459380 | C35: 1170000200 | D35: Bonds Short Term | E35: BME6P3KF4205 | F35: 0 | G35: -2.9108802e+08 | H35: -2.9108802e+08
... A40: 45790 | B40: SV01459387 | C40: 1568000040 | D40: Sus Asst Lt Bd A/R Dispty | E40: BME6P3KF4-Cash | F40: 0 | G40: -3.0313088e+08 | H40: -3.0313088e+08
A41: 45790 | B41: SV01459387 | C41: 1568000090 | D41: FEDERAL INCOME TAX RECEIVABLE | E41: BME6P3KF4-Cash | F41: 3035716 | G41: 0 | H41: 3035716 | I41: Tested under investement FDR_Encashment & Renewal
A42: 45790 | B42: SV01459387 | C42: 4430005300 | D42: Inv Exp and Taxes O/T RE | E42: BME6P3KF4-Cash | F42: 100000 | G42: 0 | H42: 100000
A43: 45790 | B43: SV01459387 | C43: 1012603028 | D43: SCB Saadiq SND A/C | E43: BME6P3KF4-Cash | F43: 3.0313088e+08 | G43: 0 | H43: 3.0313088e+08
A44: 45819 | B44: SJ01470497 | C44: 1170000200 | D44: Bonds Short Term | E44: BME6QARX1205 | F44: 0 | G44: -2.5583333e+08 | H44: -2.5583333e+08
A45: 45819 | B45: SJ01470497 | C45: 4390000052 | D45: Int Rec From Bonds St | E45: BME6QARX1205 | F45: 0 | G45: -15477917 | H45: -15477917
A46: 45819 | B46: SJ01470497 | C46: 1568000040 | D46: Sus Asst Lt Bd A/R Dispty | E46: BME6QARX1205 | F46: 2.7131125e+08 | G46: 0 | H46: 2.7131125e+08
A47: 45835 | B47: SJ01476447 | C47: 1170000200 | D47: Bonds Short Term | E47: BME6QARX1205 | F47: 2.5583333e+08 | G47: 0 | H47: 2.5583333e+08
A48: 45835 | B48: SJ01476447 | C48: 1568000040 | D48: Sus Asst Lt Bd A/R Dispty | E48: BME6QARX1205 | F48: 2.7146454e+08 | G48: 0 | H48: 2.7146454e+08
...

Sheet Tax paid for 2024
A1: Nurul Faruk Hasan & Co
A2: Chartered Accountants
A4: Client name: American Life Insurance Company, Bangladesh Branch (MetLife)
A5: Accounting period: 01 January 2025 to 31 December 2025
A6: Prepared by: Md. Tamzid | G6: Date: 25 February 2026
A7: Reviewed by: Ranti Saha | G7: Date: 25 February 2026
A8: Further reviewed by: Faruk Uddin Ahammed, FCA | G8: Date: 04 March 2026
A9: Subject: Break up of tax paid for 2024
A12: Particulars | B12: Amount paid | C12: Checked with | D12: Submission Date | E12: Remarks
A13: 3rd Installment 2025-2026 | B13: 530000000 | C13: Tax Challan/Money receipt of tax submission | D13: 45320
A14: 4th Installment 2025-2026 | B14: 651500000 | C14: Tax Challan/Money receipt of tax submission | D14: 45455
A15: Balance | B15: =SUM(B13:B14)
A16: Additional Tax Demand from ADR for the year 2018 | B16: 41958324 | C16: Checked with ADR for the year 2018
A17: Deposit Govt. Treasury for the Appellate Tribunal of AY: 2021:22 | B17: 9137724 | C17: Checked with Deposit of Tribunal Money
A18: Excess Payment | B18: -200010091 | C18: As per Tax Return 2023 under "39 Deficit or Excess (refundable)" | E18: =Remarks!A3
A19: Total Tax paid for prior years | B19: =SUM(B15:B18) | C19: Checked with Financial Statements
A20: Amount Shown in FS | B20: ='Top sheet'!D28
A21: Difference | B21: =B19-B20
A25: Conclusion:
A26: No exception noted
A46: Since the amount falls below the CTT threshold, the difference has been considered immaterial and has been disregarded.

Sheet Regulation
A1: Nurul Faruk Hasan & Co
A2: Chartered Accountants
A4: Client name: American Life Insurance Company, Bangladesh Branch (MetLife)
A5: Accounting period: 01 January 2025 to 31 December 2025
A6: Prepared by: Md. Tamzid | G6: Date: 25 February 2026
A7: Reviewed by: Ranti Saha | G7: Date: 25 February 2026
A8: Further reviewed by: Faruk Uddin Ahammed, FCA | G8: Date: 04 March 2026
A9: Subject: Provision of Income Tax Act 2023 and Provision of Income Tax Ordinance 1984
A10: Purpose: To ensure whether management complies the local regulation
A12: According to the provision of the 4th schedule of Insurance Act, an insurer shall select the higher one of the following two methods for determining the profit of the insurer.
B13: 1 | C13: Total income based on "Gross External Incomings"
B14: 2 | C14: Total income based on "Actuarial Valuation"
A16: Fourth schedule, Income Tax Act 2023. | I16: Fourth schedule, Income Tax Ordinance 1984.
A73: Conclusion:
A74: As per ET's checking during the audit, ET did not note any departure from the provision of the regulation.

Sheet Return 2024
A1: Nurul Faruk Hasan & Co
A2: Chartered Accountants
A4: Client name: American Life Insurance Company, Bangladesh Branch (MetLife)
A5: Accounting period: 01 January 2025 to 31 December 2025
A6: Prepared by: Md. Tamzid | G6: Date: 25 February 2026
A7: Reviewed by: Ranti Saha | G7: Date: 25 February 2026
A8: Further reviewed by: Faruk Uddin Ahammed, FCA | G8: Date: 04 March 2026
A9: Subject: Comparison of two methods mentioned in the Income Tax Ordinance 1984
A10: Purpose: To ensure whether management complies the local regulation
A12: ET has checked the income tax return for the year end 31 December 2022
A13: Sl no | B13: Particulars | G13: Amount
A14: 1 | B14: Total income based on "Gross External Incomings" | G14: 6033367859
A15: 2 | B15: Total income based on "Actuarial Valuation" | G15: 5595885983
B16: Higher of above two | G16: =MAX(G14,G15) | H16: Check "Comparison of two methods" below
A19: Based on ET's checking, it appears that the method of calculating total income using "Gross External Incomings" results in a higher tax liability compared to the "Actuarial Valuation" method. Therefore, it is preferable to make provisions for taxes based on the income determined under the Gross External Incomings method.
A22: Comparison of two methods: | J22: Total income based on "Actuarial Valuation" | Y22: Total income based on "Gross External Incomings"
J44: Actuarial valuation report to confirm the surplus:
A63: Conclusion:
A64: As per ET's checking during the audit, ET did not note any departure from the provision of the regulation.

Sheet GL
A1: Nurul Faruk Hasan & Co
A2: Chartered Accountants
A4: Client name: American Life Insurance Company, Bangladesh Branch (MetLife)
A5: Accounting period: 01 January 2025 to 31 December 2025
A6: Prepared by: Md. Tamzid | G6: Date: 25 February 2026
A7: Reviewed by: Ranti Saha | G7: Date: 25 February 2026
A8: Further reviewed by: Faruk Uddin Ahammed, FCA | G8: Date: 04 March 2026
A9: Subject: Transaction during the year
A12: GL Code: | B12: 2700000020
A13: LEDGER | B13: FISCAL_YEAR | C13: ACCOUNTING_PERIOD | D13: ACCOUNT | E13: DESCR | F13: PRODUCT | G13: OPERATING_UNIT | H13: DEPTID | I13: JOURNAL_ID | J13: JOURNAL_DATE | K13: FOREIGN_CURRENCY | L13: Sum of FOREIGN_AMOUNT
A14: LSTAT_BASE | B14: 2025 | C14: 12 | D14: 2700000020 | E14: Fgnn Tx Curr Due & Accr Operat | F14: 360004 | G14: 36320000 | H14: 50992000 | I14: 680598 | J14: 46022 | K14: BDT | L14: -3646339.1
A15: LSTAT_BASE | B15: 2025 | C15: 12 | D15: 2700000020 | E15: Fgnn Tx Curr Due & Accr Operat | F15: 361096 | G15: 36310000 | H15: 50992000 | I15: 680598 | J15: 46022 | K15: BDT | L15: 7.7969196e+08
A16: LSTAT_BASE | B16: 2025 | C16: 12 | D16: 2700000020 | E16: Fgnn Tx Curr Due & Accr Operat | F16: 361099 | G16: 36320000 | H16: 50992000 | I16: 680598 | J16: 46022 | K16: BDT | L16: -4800352.8
A17: LSTAT_BASE | B17: 2025 | C17: 12 | D17: 2700000020 | E17: Fgnn Tx Curr Due & Accr Operat | F17: 361396 | G17: 36310000 | H17: 50992000 | I17: 680598 | J17: 46022 | K17: BDT | L17: 29218267
A18: LSTAT_BASE | B18: 2025 | C18: 12 | D18: 2700000020 | E18: Fgnn Tx Curr Due & Accr Operat | F18: 363099 | G18: 36230000 | H18: 50992000 | I18: 680598 | J18: 46022 | K18: BDT | L18: 1.1290945e+08
A19: LSTAT_BASE | B19: 2025 | C19: 12 | D19: 2700000020 | E19: Fgnn Tx Curr Due & Accr Operat | F19: 364399 | G19: 36400000 | H19: 50992000 | I19: 680598 | J19: 46022 | K19: BDT | L19: 10945384
A20: LCOMN_BASE | B20: 2025 | C20: 1 | D20: 2700000020 | E20: Fgnn Tx Curr Due & Accr Operat | F20: 360004 | G20: 36320000 | H20: 50992000 | I20: 625223 | J20: 45688 | K20: BDT | L20: -43533618
A21: LCOMN_BASE | B21: 2025 | C21: 1 | D21: 2700000020 | E21: Fgnn Tx Curr Due & Accr Operat | F21: 361096 | G21: 36310000 | H21: 50992000 | I21: 625223 | J21: 45688 | K21: BDT | L21: -3630732
A22: LCOMN_BASE | B22: 2025 | C22: 1 | D22: 2700000020 | E22: Fgnn Tx Curr Due & Accr Operat | F22: 361099 | G22: 36320000 | H22: 50992000 | I22: 625223 | J22: 45688 | K22: BDT | L22: -58797445
A23: LCOMN_BASE | B23: 2025 | C23: 1 | D23: 2700000020 | E23: Fgnn Tx Curr Due & Accr Operat | F23: 361396 | G23: 36310000 | H23: 50992000 | I23: 625223 | J23: 45688 | K23: BDT | L23: 4169222
A24: LCOMN_BASE | B24: 2025 | C24: 1 | D24: 2700000020 | E24: Fgnn Tx Curr Due & Accr Operat | F24: 363099 | G24: 36230000 | H24: 50992000 | I24: 625223 | J24: 45688 | K24: BDT | L24: -1836985
A25: LCOMN_BASE | B25: 2025 | C25: 1 | D25: 2700000020 | E25: Fgnn Tx Curr Due & Accr Operat | F25: 364399 | G25: 36400000 | H25: 50992000 | I25: 625223 | J25: 45688 | K25: BDT | L25: 2372483
... A165: LCOMN_BASE | B165: 2025 | C165: 12 | D165: 2700000020 | E165: Fgnn Tx Curr Due & Accr Operat | F165: 364399 | G165: 36400000 | H165: 50992000 | I165: 681737 | J165: 46022 | K165: BDT | L165: -3.9218662e+08
D166: Total | L166: =SUM(L14:L165)
A169: GL Code: | B169: 1568000094
A170: LEDGER | B170: FISCAL_YEAR | C170: ACCOUNTING_PERIOD | D170: ACCOUNT | E170: DESCR | F170: PRODUCT | G170: OPERATING_UNIT | H170: DEPTID | I170: JOURNAL_ID | J170: JOURNAL_DATE | K170: FOREIGN_CURRENCY | L170: Sum of FOREIGN_AMOUNT
A171: LSTAT_BASE | B171: 2025 | C171: 5 | D171: 1568000094 | E171: INTL INCOME TAX RECEIVABLE | F171: 360004 | G171: 36320000 | H171: 50992000 | I171: 642178 | J171: 45808 | K171: BDT | L171: -37242
A172: LCOMN_BASE | B172: 2025 | C172: 3 | D172: 1568000094 | E172: INTL INCOME TAX RECEIVABLE | F172: 360004 | G172: 36320000 | H172: 50992000 | I172: 633120 | J172: 45747 | K172: BDT | L172: 530000000
A173: LCOMN_BASE | B173: 2025 | C173: 5 | D173: 1568000094 | E173: INTL INCOME TAX RECEIVABLE | F173: 360004 | G173: 36320000 | H173: 50992000 | I173: 642181 | J173: 45808 | K173: BDT | L173: 37242
A174: LCOMN_BASE | B174: 2025 | C174: 6 | D174: 1568000094 | E174: INTL INCOME TAX RECEIVABLE | F174: 360004 | G174: 36320000 | H174: 50992000 | I174: 648846 | J174: 45838 | K174: BDT | L174: 651500000
A175: LCOMN_BASE | B175: 2025 | C175: 7 | D175: 1568000094 | E175: INTL INCOME TAX RECEIVABLE | F175: 360004 | G175: 36320000 | H175: 50992000 | I175: 654821 | J175: 45869 | K175: BDT | L175: 41958324
A176: LCOMN_BASE | B176: 2025 | C176: 9 | D176: 1568000094 | E176: INTL INCOME TAX RECEIVABLE | F176: 360004 | G176: 36320000 | H176: 50992000 | I176: 664227 | J176: 45930 | K176: BDT | L176: 92000000
A177: LCOMN_BASE | B177: 2025 | C177: 9 | D177: 1568000094 | E177: INTL INCOME TAX RECEIVABLE | F177: 360004 | G177: 36320000 | H177: 50992000 | I177: 665692 | J177: 45930 | K177: BDT | L177: 9137724
A178: LCOMN_BASE | B178: 2025 | C178: 12 | D178: 1568000094 | E178: INTL INCOME TAX RECEIVABLE | F178: 360004 | G178: 36320000 | H178: 50992000 | I178: 680597 | J178: 46022 | K178: BDT | L178: -1.3962024e+09
A179: LCOMN_BASE | B179: 2025 | C179: 12 | D179: 1568000094 | E179: INTL INCOME TAX RECEIVABLE | F179: 360004 | G179: 36320000 | H179: 50992000 | I179: 680592 | J179: 46022 | K179: BDT | L179: -41958325
D180: Total | L180: =SUM(L171:L179)

Sheet PBC GL Tax Provision
A1: Nurul Faruk Hasan & Co
A2: Chartered Accountants
A4: Client name: American Life Insurance Company, Bangladesh Branch (MetLife)
A5: Accounting period: 01 January 2024 to 31 December 2024
A6: Prepared by: Md. Tamzid | F6: Date: 25 February 2025
A7: Reviewed by: Ranti Saha | F7: Date: 25 February 2025
A8: Further reviewed by: Faruk Uddin Ahammed, FCA | F8: Date: 04 March 2025
A9: Subject: GL of incoem tax provision
A11: Year | B11: Period | C11: Source | D11: Account | E11: Descr | F11: Product | G11: Oper Unit | H11: Dept | I11: Sum Amount | J11: Currency | K11: Journal ID | L11: Date | M11: Ref | N11: Type
A12: 2022 | B12: 1 | C12: 387 | D12: 1568000090 | E12: FEDERAL INCOME TAX RECEIVABLE | F12: 360004 | G12: 36320000 | H12: 50601000 | I12: 110496.1 | J12: BDT | K12: SV01021451 | L12: 44587 | N12: A
A13: 2022 | B13: 1 | C13: 387 | D13: 1568000090 | E13: FEDERAL INCOME TAX RECEIVABLE | F13: 360004 | G13: 36320000 | H13: 50601000 | I13: 2730000 | J13: BDT | K13: SV01016883 | L13: 44574 | N13: A
A14: 2022 | B14: 1 | C14: 387 | D14: 1568000090 | E14: FEDERAL INCOME TAX RECEIVABLE | F14: 360004 | G14: 36320000 | H14: 50601000 | I14: 3720351.6 | J14: BDT | K14: SV01016410 | L14: 44573 | N14: A
A15: 2022 | B15: 1 | C15: 387 | D15: 1568000090 | E15: FEDERAL INCOME TAX RECEIVABLE | F15: 360004 | G15: 36320000 | H15: 50601000 | I15: 24582741 | J15: BDT | K15: SV01020021 | L15: 44582 | N15: A
A16: 2022 | B16: 1 | C16: 387 | D16: 1568000090 | E16: FEDERAL INCOME TAX RECEIVABLE | F16: 360004 | G16: 36320000 | H16: 50601000 | I16: 44846771 | J16: BDT | K16: SV01023081 | L16: 44592 | N16: A
A17: 2022 | B17: 1 | C17: 387 | D17: 1568000090 | E17: FEDERAL INCOME TAX RECEIVABLE | F17: 361396 | G17: 36310000 | H17: 50601000 | I17: 527261.84 | J17: BDT | K17: SV01023081 | L17: 44592 | N17: A
A18: 2022 | B18: 1 | C18: B06 | D18: 1568000090 | E18: FEDERAL INCOME TAX RECEIVABLE | F18: 360004 | G18: 36320000 | H18: 50992000 | I18: 90961.65 | J18: BDT | K18: 0000435762 | L18: 44592 | N18: A
A19: 2022 | B19: 1 | C19: B07 | D19: 1568000090 | E19: FEDERAL INCOME TAX RECEIVABLE | F19: 360004 | G19: 36320000 | H19: 50992000 | I19: 75000 | J19: BDT | K19: 0000436696 | L19: 44592 | N19: A
A20: 2022 | B20: 1 | C20: B14 | D20: 1568000090 | E20: FEDERAL INCOME TAX RECEIVABLE | F20: 360004 | G20: 36320000 | H20: 50601000 | I20: 32.43 | J20: BDT | K20: 0000436377 | L20: 44592 | N20: A
A21: 2022 | B21: 1 | C21: B15 | D21: 7180000005 | E21: Fgn Exp Curr Operations | F21: 360004 | G21: 36320000 | H21: 50992000 | I21: 63668171 | J21: BDT | K21: 0000437911 | L21: 44592 | N21: E
A22: 2022 | B22: 1 | C22: B15 | D22: 7180000005 | E22: Fgn Exp Curr Operations | F22: 361096 | G22: 36310000 | H22: 50992000 | I22: 74947401 | J22: BDT | K22: 0000437911 | L22: 44592 | N22: E
A23: 2022 | B23: 1 | C23: B15 | D23: 7180000005 | E23: Fgn Exp Curr Operations | F23: 361099 | G23: 36320000 | H23: 50992000 | I23: 62896373 | J23: BDT | K23: 0000437911 | L23: 44592 | N23: E
A24: 2022 | B24: 1 | C24: B15 | D24: 7180000005 | E24: Fgn Exp Curr Operations | F24: 361396 | G24: 36310000 | H24: 50992000 | I24: -1706200 | J24: BDT | K24: 0000437911 | L24: 44592 | N24: E
A25: 2022 | B25: 1 | C25: B15 | D25: 7180000005 | E25: Fgn Exp Curr Operations | F25: 363099 | G25: 36230000 | H25: 50992000 | I25: 2862747 | J25: BDT | K25: 0000437911 | L25: 44592 | N25: E
A26: 2022 | B26: 1 | C26: B15 | D26: 7180000005 | E26: Fgn Exp Curr Operations | F26: 364399 | G26: 36400000 | H26: 50992000 | I26: 5706102 | J26: BDT | K26: 0000437911 | L26: 44592 | N26: E
A27: 2022 | B27: 2 | C27: 387 | D27: 1568000090 | E27: FEDERAL INCOME TAX RECEIVABLE | F27: 360004 | G27: 36320000 | H27: 50601000 | I27: 1554764.5 | J27: BDT | K27: SV01027890 | L27: 44605 | N27: A
A28: 2022 | B28: 2 | C28: 387 | D28: 1568000090 | E28: FEDERAL INCOME TAX RECEIVABLE | F28: 360004 | G28: 36320000 | H28: 50601000 | I28: 6881195 | J28: BDT | K28: SV01030470 | L28: 44614 | N28: A
A29: 2022 | B29: 2 | C29: 387 | D29: 1568000090 | E29: FEDERAL INCOME TAX RECEIVABLE | F29: 360004 | G29: 36320000 | H29: 50601000 | I29: 8911761.2 | J29: BDT | K29: SV01032585 | L29: 44620 | N29: A
A30: 2022 | B30: 2 | C30: 387 | D30: 1568000090 | E30: FEDERAL INCOME TAX RECEIVABLE | F30: 360004 | G30: 36320000 | H30: 50601000 | I30: 22569650 | J30: BDT | K30: SV01032582 | L30: 44619 | N30: A
A31: 2022 | B31: 2 | C31: 387 | D31: 1568000090 | E31: FEDERAL INCOME TAX RECEIVABLE | F31: 361396 | G31: 36310000 | H31: 50601000 | I31: 104956.5 | J31: BDT | K31: SV01030968 | L31: 44615 | N31: A
A32: 2022 | B32: 2 | C32: 387 | D32: 1568000090 | E32: FEDERAL INCOME TAX RECEIVABLE | F32: 361396 | G32: 36310000 | H32: 50601000 | I32: 212340.62 | J32: BDT | K32: SV01032582 | L32: 44619 | N32: A
A33: 2022 | B33: 2 | C33: 387 | D33: 1568000090 | E33: FEDERAL INCOME TAX RECEIVABLE | F33: 361396 | G33: 36310000 | H33: 50601000 | I33: 243752.15 | J33: BDT | K33: SV01030470 | L33: 44614 | N33: A
A34: 2022 | B34: 2 | C34: 387 | D34: 1568000090 | E34: FEDERAL INCOME TAX RECEIVABLE | F34: 361396 | G34: 36310000 | H34: 50601000 | I34: 367245.92 | J34: BDT | K34: SV01027890 | L34: 44605 | N34: A
A35: 2022 | B35: 2 | C35: 387 | D35: 1568000090 | E35: FEDERAL INCOME TAX RECEIVABLE | F35: 361396 | G35: 36310000 | H35: 50601000 | I35: 384414.29 | J35: BDT | K35: SV01032585 | L35: 44620 | N35: A
A36: 2022 | B36: 2 | C36: B06 | D36: 1568000090 | E36: FEDERAL INCOME TAX RECEIVABLE | F36: 360004 | G36: 36320000 | H36: 50992000 | I36: 90961.65 | J36: BDT | K36: 0000440397 | L36: 44620 | N36: A
A37: 2022 | B37: 2 | C37: B06 | D37: 1568000090 | E37: FEDERAL INCOME TAX RECEIVABLE | F37: 364099 | G37: 36240000 | H37: 50992000 | I37: 10807.96 | J37: BDT | K37: 0000441401 | L37: 44620 | N37: A
A38: 2022 | B38: 2 | C38: B07 | D38: 1568000090 | E38: FEDERAL INCOME TAX RECEIVABLE | F38: 360004 | G38: 36320000 | H38: 50992000 | I38: 75000 | J38: BDT | K38: 0000441092 | L38: 44620 | N38: A
A39: 2022 | B39: 2 | C39: B15 | D39: 7180000005 | E39: Fgn Exp Curr Operations | F39: 360004 | G39: 36320000 | H39: 50992000 | I39: -63668171 | J39: BDT | K39: 0000437911 | L39: 44593 | N39: E
A40: 2022 | B40: 2 | C40: B15 | D40: 7180000005 | E40: Fgn Exp Curr Operations | F40: 360004 | G40: 36320000 | H40: 50992000 | I40: 121698935 | J40: BDT | K40: 0000442498 | L40: 44620 | N40: E
A41: 2022 | B41: 2 | C41: B15 | D41: 7180000005 | E41: Fgn Exp Curr Operations | F41: 361096 | G41: 36310000 | H41: 50992000 | I41: -74947401 | J41: BDT | K41: 0000437911 | L41: 44593 | N41: E
A42: 2022 | B42: 2 | C42: B15 | D42: 7180000005 | E42: Fgn Exp Curr Operations | F42: 361096 | G42: 36310000 | H42: 50992000 | I42: 161690350 | J42: BDT | K42: 0000442498 | L42: 44620 | N42: E
...

Sheet Tax Calculation PBC
B1: Nurul Faruk Hasan & Co
B2: Chartered Accountants
B4: Client name: American Life Insurance Company, Bangladesh Branch (MetLife)
B5: Accounting period: 01 January 2025 to 31 December 2025
B7: PBC: Calculation of income tax provision prepared in line of actuarial valuation of life insurance fund
B8: Purpose: To confirm the amount of tax shown in the financial statements
B10: A. Surplus & Tax Calculation determined by actuary
B11: Surplus & Tax Calculation
B12: PARTICULARS | C12: SH | D12: PARL | E12: NPARL | F12: TKF | G12: A&H | H12: GRP | I12: TOTAL | J12: Audit checking
B13: Life Fund : Pre-tax | C13: =C49 | D13: =D49 | E13: =E49 | F13: =F49 | G13: =G49 | H13: =H49 | I13: =SUM(C13:H13) | J13: Life fund balance before considering taxation
B14: Amount of Mathematical Reserves | C14: 0 | D14: =C61 | E14: =D61 | F14: =E61 | G14: =F61 | H14: =G61 | I14: =SUM(C14:H14) | J14: Draft Mathematical reserve for 2024 from Actuarial Valuation report
B15: Surplus - ITD | C15: =C13-C14 | D15: =D13-D14 | E15: =E13-E14 | F15: =F13-F14 | G15: =G13-G14 | H15: =H13-H14 | I15: =SUM(C15:H15)
B16: + Bonuses on policies as at Dec 2024 excluding New Business | D16: 5.6294018e+09 | I16: =SUM(C16:H16)
B17: - Surplus Brought Forward | D17: 6.0638249e+09 | I17: =SUM(C17:H17)
B18: Total Profit Arising During the Period | C18: =C15-C17+C16 | D18: =D15-D17+D16 | E18: =E15-E17+E16 | F18: =F15-F17+F16 | G18: =G15-G17+G16 | H18: =H15-H17+H16 | I18: =SUM(C18:H18)
B19: Admissible Expenses | D19: =D18*0.9*0.75 | I19: =SUM(C19:H19) | J19: Admissible Expenses as per Fourth schedule of Income Tax Act 2023
B20: Total income on life business/income on shareholders portion | C20: =C18-C19 | D20: =D18-D19 | E20: =E18-E19 | F20: =F18-F19 | G20: =G18-G19 | H20: =H18-H19 | I20: =SUM(C20:H20)
B21: Disallowed expenses under section 49-55 | C21: =(C20/$I$20)*$I$21 | D21: =(D20/$I$20)*$I$21 | E21: =(E20/$I$20)*$I$21 | F21: =(F20/$I$20)*$I$21 | G21: =(G20/$I$20)*$I$21 | H21: =(H20/$I$20)*$I$21
B22: Total Income for Tax Base after disallowance | C22: =C20+C21 | D22: =D20+D21 | E22: =E20+E21 | F22: =F20+F21 | G22: =G20+G21 | H22: =H20+H21 | I22: =I20+I21
B23: Income tax @40% | C23: =ROUND(C22*0.4,0) | D23: =ROUND(D22*0.4,0) | E23: =ROUND(E22*0.4,0) | F23: =ROUND(F22*0.4,0) | G23: =ROUND(G22*0.4,0) | H23: =ROUND(H22*0.4,0) | I23: =SUM(C23:H23) | J23: Provision for Tax - @40% for non listed Life Insurance company
B24: Tax 2023 | C24: 37223750 | D24: -86557880 | E24: -3.5234473e+08 | F24: -5954065 | G24: 324991.99 | H24: -77254667 | I24: =SUM(C24:H24) | J24: Last Year under provision
B25: Profit Arising during the period - After Tax | C25: =C18-C23 | D25: =D18-D23-D24 | E25: =E18-E23-E24 | F25: =F18-F23-F24 | G25: =G18-G23-G24 | H25: =H18-H23-H24 | I25: =SUM(C25:H25)
B26: PH | D26: =D25*0.9 | I26: =SUM(C26:H26)
B27: SH | C27: =C25-C26 | D27: =D25-D26 | E27: =E25-E26 | F27: =F25-F26 | G27: =G25-G26 | H27: =H25-H26 | I27: =SUM(C27:H27)
B30: PHDL | D30: =D26+D17-D16 | I30: =SUM(C30:H30)
B31: Methodology
B32: 1. Amount of Mathematical Reserves and Bonuses on policies have been derived from provisional actuarial estimates and balances.
B35: B. Amount of current year tax provision
B37: Provision for Current Year | C37: =C23 | D37: =D23 | E37: =E23 | F37: =F23 | G37: =G23 | H37: =H23 | I37: =SUM(C37:H37)
C38: =C37/$I$37 | D38: =D37/$I$37 | E38: =E37/$I$37 | F38: =F37/$I$37 | G38: =G37/$I$37 | H38: =H37/$I$37
B39: Tax paid in advance & deducted at source | C39: =$I$39*C$38 | D39: =$I$39*D$38 | E39: =$I$39*E$38 | F39: =$I$39*F$38 | G39: =$I$39*G$38 | H39: =$I$39*H$38 | I39: ='Top sheet'!E27
B44: C. Amount of Pre-tax Life Fund determined in Actuarial valuation
B46: Particulars | C46: SH | D46: PAR Life | E46: Non Par Life | F46: Takaful | G46: A&H | H46: Group | I46: Non Par Life Total | J46: Total
B47: Post tax Life fund | C47: 1411810901 | D47: 94080658821 | E47: 51773293801 | F47: 6132589482 | G47: 68210915 | H47: 1350727521 | I47: =SUM(E47:H47) | J47: =C47+D47+I47
B48: Tax | C48: 1.0032468e+09 | D48: 1.0687311e+09 | E48: 6.5419981e+08 | F48: 58782697 | G48: 14003684 | H48: 56988550 | I48: =SUM(E48:H48) | J48: =C48+D48+I48
B49: Pre tax | C49: =C47+C48 | D49: =D47+D48 | E49: =E47+E48 | F49: =F47+F48 | G49: =G47+G48 | H49: =H47+H48 | I49: =I47+I48 | J49: =SUM(C49+D49+I49)
K52: Audit checking
J53: 154819597332 | K53: Closing balance of life insurance fund as per revenue account
J54: 2.8536468e+09 | K54: Provision for income tax for the period as per revenue account
J55: =SUM(J53:J54) | K55: Amount of pre tax life insurance fund as per actuarial valuation
...

Sheet Remarks
A1: Tickmarks
A3: {a}

Sheet Par NPar
A1: Nurul Faruk Hasan & Co
A2: Chartered Accountants
A4: Client name: American Life Insurance Company, Bangladesh Branch (MetLife)
A5: Accounting period: 01 January 2022 to 31 December 2022
A6: Prepared by: Md. Enamul Haq Rudro
A7: Reviewed by: Ranti Saha
A9: Subject: Par/Non-Par allocation for income tax provision
A11: Allocation of Par and Non-Par of income tax provision (note 17):
A13: Particulars | B13: SH | C13: PARL | D13: NPARL | E13: TKF | F13: A&H | G13: GRP | H13: TOTAL | I13: ET checking
A14: Provision for income tax Opening balance | B14: 245467005 | C14: 280578435 | D14: 235978574 | E14: 270237 | F14: 2114443 | G14: 31792640 | H14: =SUM(B14:G14) | I14: Checked with prior year FS
B15: =B14/$H$14 | C15: =C14/$H$14 | D15: =D14/$H$14 | E15: =E14/$H$14 | F15: =F14/$H$14 | G15: =G14/$H$14 | H15: =H14/$H$14
A16: Provision made during the year
A17: Income tax @40% | B17: 8.2288817e+08 | C17: 9.0674879e+08 | D17: 9.8182673e+08 | E17: 870457.05 | F17: 8577265.8 | G17: 1.5487827e+08 | H17: =SUM(B17:G17) | I17: 40% tax as per total income based on actuarial valuation
B18: =B17/$H$17 | C18: =C17/$H$17 | D18: =D17/$H$17 | E18: =E17/$H$17 | F18: =F17/$H$17 | G18: =G17/$H$17 | H18: =H17/$H$17
A19: Tax 2021 | B19: -17833827 | C19: -15099623 | D19: -15743265 | E19: -25446.129 | F19: -126912.89 | G19: -2366000.5 | H19: =SUM(B19:G19)
B20: =B19/$H$19 | C20: =C19/$H$19 | D20: =D19/$H$19 | E20: =E19/$H$19 | F20: =F19/$H$19 | G20: =G19/$H$19 | H20: =H19/$H$19
B21: =SUM(B17:B19) | C21: =SUM(C17:C19) | D21: =SUM(D17:D19) | E21: =SUM(E17:E19) | F21: =SUM(F17:F19) | G21: =SUM(G17:G19) | H21: =SUM(H17:H19)
A22: Less: Payments / adjustments made during the year (Note 17.1) | B22: 7.0230021e+08 | C22: 7.8545539e+08 | D22: 7.7266257e+08 | E22: 755037.67 | F22: 6810729.3 | G22: 1.1565138e+08 | H22: =SUM(B22:G22)
A26: 17.1a Tax paid in advance & deducted at source | B26: 4.2065887e+08 | C26: 4.6352826e+08 | D26: 5.0190796e+08 | E26: 444975.99 | F26: 4384682 | G26: 79173480 | H26: =SUM(B26:G26) | I26: Based on the current year provision amount as per actuarial valuation
B27: =B26/$H$26 | C27: =C26/$H$26 | D27: =D26/$H$26 | E27: =E26/$H$26 | F27: =F26/$H$26 | G27: =G26/$H$26 | H27: =H26/$H$26
A28: 17.1b Tax paid for 2021 | B28: 2.8164134e+08 | C28: 3.2192713e+08 | D28: 2.7075461e+08 | E28: 310061.68 | F28: 2426047.3 | G28: 36477904 | H28: =SUM(B28:G28) | I28: Based on the opening balance of Life Insurance Fund
B29: =B28/$H$28 | C29: =C28/$H$28 | D29: =D28/$H$28 | E29: =E28/$H$28 | F29: =F28/$H$28 | G29: =G28/$H$28 | H29: =H28/$H$28
A30: Note 17.1a + Note 17.1b (Total of above two) | B30: 7.0230021e+08 | C30: 7.8545539e+08 | D30: 7.7266257e+08 | E30: 755037.67 | F30: 6810729.3 | G30: 1.1565138e+08 | H30: =SUM(B30:G30)
